Workbook

Sheet Read me
A1: Renewal tracker: a mock-up of the CRM renewal model
A3: Purpose | B3: Shows the numbers the CRM would hold: renewals by month and quarter, by status, by product line, and a forecast driven by Renewal Status x countdown.
A4: Today | B4: Pipeline!B2 = 20 Oct 2026 (exercise date). Use =TODAY() in live use.
A5: Triage | B5: Rank, why first, next action, one lead owner (Me / CSM / Finance / Legal) plus who does what, due date, and today's escalations. Sorted by rank; edit the rank on the Pipeline tab.
A6: Probability | B6: Renewal Status x days to renewal. Late statuses rise as the date gets closer; early statuses fall. Overdue has its own, lower column.
A7: Auto-renewals | B7: Own statuses: Renewing: no blockers / Billing blocker / At risk (before or after the notice deadline) / Notice received / Renewed. A red status cell means the status does not match the renewal type.
A8: Usage rule | B8: Usage +20%: renew as is plus an Upsell opportunity and task (no automatic charge). Usage -20%: flag the CSM; auto-renewals move to At risk.
A9: Forecast of the forecast | B9: Weighted today vs weighted by 30 Oct if this week's actions move each status to its target.
A10: Overdue rule | B10: Overdue renewals are Late. They count in the quarter only if the expected close date is on or before quarter end; otherwise 0% for the quarter.
A11: Forecast | B11: Weighted new ARR = new ARR from product lines x probability. Buckets: On time, Late (still in quarter), Slips quarter. Lost comes from the product lines.
A12: Products | B12: The Renewals Manager only sets the line type (Renewal / Upsell / Downgrade / Churn) and the new numbers. Original ARR, list price, new ARR and Δ (green/red) recalculate; the renewal value already includes the uplift. Upsell lines open a linked Upsell opportunity.
A13: Churn | B13: Set on the opportunity: churned amount (from the lines), category (Regrettable = revenue lost for good; Non-regrettable = revenue kept, e.g. self-hosted moving to n8n Cloud) and a granular reason.
A14: Colour code | B14: Blue on yellow = input. Black = formula. Green text = link to another tab. Red/amber/green fills = risk.
A15: Source | B15: Customers, numbers and policies are fictional, from the challenge brief. Plan names and downgrade prices are assumptions.

Sheet Triage
A1: Triage: what I do first, who owns it, by when
A2: Ranked by slack (days left vs work still needed) x ARR at risk. Linked to Pipeline: change a rank there and this list re-sorts.
A4: Rank | B4: Customer | C4: ARR (€) | D4: Renewal date | E4: Days | F4: Renewal Status | G4: Why first | H4: Next action | I4: Owner | J4: Who does what | K4: Due | L4: Escalate today
A5: 1 | B5: =INDEX(Pipeline!$A$5:$A$14,MATCH($A5,Pipeline!$Y$5:$Y$14,0)) -> Northwind Logistics | C5: =INDEX(Pipeline!$B$5:$B$14,MATCH($A5,Pipeline!$Y$5:$Y$14,0)) -> 48000 | D5: =INDEX(Pipeline!$C$5:$C$14,MATCH($A5,Pipeline!$Y$5:$Y$14,0)) -> 46324 | E5: =INDEX(Pipeline!$J$5:$J$14,MATCH($A5,Pipeline!$Y$5:$Y$14,0)) -> 9 | F5: =INDEX(Pipeline!$G$5:$G$14,MATCH($A5,Pipeline!$Y$5:$Y$14,0)) -> Engaging customer | G5: =INDEX(Pipeline!$Z$5:$Z$14,MATCH($A5,Pipeline!$Y$5:$Y$14,0))&"" -> Biggest near-term ARR, 9 days out, no quote, signed 3 days late last year. One hour of work removes most of the risk. | H5: =INDEX(Pipeline!$V$5:$V$14,MATCH($A5,Pipeline!$Y$5:$Y$14,0))&"" -> Quote and order form out today at €48k for e-signature; champion confirms signatory and PO need; signature booked for 27 Oct. | I5: =INDEX(Pipeline!$W$5:$W$14,MATCH($A5,Pipeline!$Y$5:$Y$14,0)) -> Me | J5: =INDEX(Pipeline!$AA$5:$AA$14,MATCH($A5,Pipeline!$Y$5:$Y$14,0))&"" -> Me: quote, order form, signatory, signature on 27 Oct | K5: =INDEX(Pipeline!$X$5:$X$14,MATCH($A5,Pipeline!$Y$5:$Y$14,0)) -> 46315 | L5: =INDEX(Pipeline!$AB$5:$AB$14,MATCH($A5,Pipeline!$Y$5:$Y$14,0))&""
A6: 2 | B6: =INDEX(Pipeline!$A$5:$A$14,MATCH($A6,Pipeline!$Y$5:$Y$14,0)) -> Vantage Freight | C6: =INDEX(Pipeline!$B$5:$B$14,MATCH($A6,Pipeline!$Y$5:$Y$14,0)) -> 21000 | D6: =INDEX(Pipeline!$C$5:$C$14,MATCH($A6,Pipeline!$Y$5:$Y$14,0)) -> 46310 | E6: =INDEX(Pipeline!$J$5:$J$14,MATCH($A6,Pipeline!$Y$5:$Y$14,0)) -> -5 | F6: =INDEX(Pipeline!$G$5:$G$14,MATCH($A6,Pipeline!$Y$5:$Y$14,0)) -> Quoted | G6: =INDEX(Pipeline!$Z$5:$Z$14,MATCH($A6,Pipeline!$Y$5:$Y$14,0))&"" -> Already overdue. The blocker is a shared inbox, not price: find a named person. | H6: =INDEX(Pipeline!$V$5:$V$14,MATCH($A6,Pipeline!$Y$5:$Y$14,0))&"" -> CSM looks up the instance owner and admin users (names, emails) in product data, to replace the shared inbox; I call and email the named person and agree a signing date. Manager confirms the grace period before access is restricted. | I6: =INDEX(Pipeline!$W$5:$W$14,MATCH($A6,Pipeline!$Y$5:$Y$14,0)) -> Me | J6: =INDEX(Pipeline!$AA$5:$AA$14,MATCH($A6,Pipeline!$Y$5:$Y$14,0))&"" -> CSM: finds the instance owner and admins Me: calls them and agrees a signing date Manager: confirms the grace period | K6: =INDEX(Pipeline!$X$5:$X$14,MATCH($A6,Pipeline!$Y$5:$Y$14,0)) -> 46316 | L6: =INDEX(Pipeline!$AB$5:$AB$14,MATCH($A6,Pipeline!$Y$5:$Y$14,0))&"" -> Yes: Manager, to agree the grace period before access is restricted
A7: 3 | B7: =INDEX(Pipeline!$A$5:$A$14,MATCH($A7,Pipeline!$Y$5:$Y$14,0)) -> Pixelforge | C7: =INDEX(Pipeline!$B$5:$B$14,MATCH($A7,Pipeline!$Y$5:$Y$14,0)) -> 26000 | D7: =INDEX(Pipeline!$C$5:$C$14,MATCH($A7,Pipeline!$Y$5:$Y$14,0)) -> 46328 | E7: =INDEX(Pipeline!$J$5:$J$14,MATCH($A7,Pipeline!$Y$5:$Y$14,0)) -> 13 | F7: =INDEX(Pipeline!$G$5:$G$14,MATCH($A7,Pipeline!$Y$5:$Y$14,0)) -> Billing blocker | G7: =INDEX(Pipeline!$Z$5:$Z$14,MATCH($A7,Pipeline!$Y$5:$Y$14,0))&"" -> Auto-renewal fails in 13 days on an expired card: involuntary churn on a green account. | H7: =INDEX(Pipeline!$V$5:$V$14,MATCH($A7,Pipeline!$Y$5:$Y$14,0))&"" -> CSM gets the billing contact today; I send a secure card-update link or switch to invoice; Finance pauses the automatic failed-payment process (reminders, retries, suspension) until the card is fixed. Renews at €26k (renewal value). | I7: =INDEX(Pipeline!$W$5:$W$14,MATCH($A7,Pipeline!$Y$5:$Y$14,0)) -> CSM | J7: =INDEX(Pipeline!$AA$5:$AA$14,MATCH($A7,Pipeline!$Y$5:$Y$14,0))&"" -> CSM: finds the billing contact Me: card-update link or switch to invoice Finance: pauses the failed-payment process | K7: =INDEX(Pipeline!$X$5:$X$14,MATCH($A7,Pipeline!$Y$5:$Y$14,0)) -> 46317 | L7: =INDEX(Pipeline!$AB$5:$AB$14,MATCH($A7,Pipeline!$Y$5:$Y$14,0))&""
A8: 4 | B8: =INDEX(Pipeline!$A$5:$A$14,MATCH($A8,Pipeline!$Y$5:$Y$14,0)) -> Halden Health | C8: =INDEX(Pipeline!$B$5:$B$14,MATCH($A8,Pipeline!$Y$5:$Y$14,0)) -> 45000 | D8: =INDEX(Pipeline!$C$5:$C$14,MATCH($A8,Pipeline!$Y$5:$Y$14,0)) -> 46333 | E8: =INDEX(Pipeline!$J$5:$J$14,MATCH($A8,Pipeline!$Y$5:$Y$14,0)) -> 18 | F8: =INDEX(Pipeline!$G$5:$G$14,MATCH($A8,Pipeline!$Y$5:$Y$14,0)) -> Not started | G8: =INDEX(Pipeline!$Z$5:$Z$14,MATCH($A8,Pipeline!$Y$5:$Y$14,0))&"" -> Red, usage -35%, champion gone, new owner unknown, 18 days left. | H8: =INDEX(Pipeline!$V$5:$V$14,MATCH($A8,Pipeline!$Y$5:$Y$14,0))&"" -> ESCALATE TODAY. CSM, me and exec sponsor meet the new owner this week. Legal checks the 8 Oct notice date. Right-sized option ready. | I8: =INDEX(Pipeline!$W$5:$W$14,MATCH($A8,Pipeline!$Y$5:$Y$14,0)) -> CSM | J8: =INDEX(Pipeline!$AA$5:$AA$14,MATCH($A8,Pipeline!$Y$5:$Y$14,0))&"" -> CSM (lead): meets the new owner, value review Exec sponsor: joins that meeting Legal: checks the 8 Oct notice date Me: escalates, prepares the right-sized option | K8: =INDEX(Pipeline!$X$5:$X$14,MATCH($A8,Pipeline!$Y$5:$Y$14,0)) -> 46318 | L8: =INDEX(Pipeline!$AB$5:$AB$14,MATCH($A8,Pipeline!$Y$5:$Y$14,0))&"" -> Yes: Manager + VP CS, exec sponsor meeting with the new owner this week
A9: 5 | B9: =INDEX(Pipeline!$A$5:$A$14,MATCH($A9,Pipeline!$Y$5:$Y$14,0)) -> Tessera Finance | C9: =INDEX(Pipeline!$B$5:$B$14,MATCH($A9,Pipeline!$Y$5:$Y$14,0)) -> 50000 | D9: =INDEX(Pipeline!$C$5:$C$14,MATCH($A9,Pipeline!$Y$5:$Y$14,0)) -> 46344 | E9: =INDEX(Pipeline!$J$5:$J$14,MATCH($A9,Pipeline!$Y$5:$Y$14,0)) -> 29 | F9: =INDEX(Pipeline!$G$5:$G$14,MATCH($A9,Pipeline!$Y$5:$Y$14,0)) -> Negotiation | G9: =INDEX(Pipeline!$Z$5:$Z$14,MATCH($A9,Pipeline!$Y$5:$Y$14,0))&"" -> MSA redlines open since September and a security review can block the PO; 29 days left. | H9: =INDEX(Pipeline!$V$5:$V$14,MATCH($A9,Pipeline!$Y$5:$Y$14,0))&"" -> ESCALATE TODAY to Legal: redline response by 30 Oct. List PO-blocking redlines, agree positions; joint redline call. Quote + security pack today. Fallback: 1-2 month extension if MSA not signed by 18 Nov. | I9: =INDEX(Pipeline!$W$5:$W$14,MATCH($A9,Pipeline!$Y$5:$Y$14,0)) -> Legal | J9: =INDEX(Pipeline!$AA$5:$AA$14,MATCH($A9,Pipeline!$Y$5:$Y$14,0))&"" -> Legal (lead): positions on PO-blocking redlines, joint call, response by 30 Oct Me: redline list, quote and security pack, runs the timeline Finance + Legal: approve the extension fallback | K9: =INDEX(Pipeline!$X$5:$X$14,MATCH($A9,Pipeline!$Y$5:$Y$14,0)) -> 46318 | L9: =INDEX(Pipeline!$AB$5:$AB$14,MATCH($A9,Pipeline!$Y$5:$Y$14,0))&"" -> Yes: Legal lead, redline response by 30 Oct; extension fallback approved
A10: 6 | B10: =INDEX(Pipeline!$A$5:$A$14,MATCH($A10,Pipeline!$Y$5:$Y$14,0)) -> Brightloop | C10: =INDEX(Pipeline!$B$5:$B$14,MATCH($A10,Pipeline!$Y$5:$Y$14,0)) -> 36000 | D10: =INDEX(Pipeline!$C$5:$C$14,MATCH($A10,Pipeline!$Y$5:$Y$14,0)) -> 46370 | E10: =INDEX(Pipeline!$J$5:$J$14,MATCH($A10,Pipeline!$Y$5:$Y$14,0)) -> 55 | F10: =INDEX(Pipeline!$G$5:$G$14,MATCH($A10,Pipeline!$Y$5:$Y$14,0)) -> Negotiation | G10: =INDEX(Pipeline!$Z$5:$Z$14,MATCH($A10,Pipeline!$Y$5:$Y$14,0))&"" -> Live negotiation; procurement sets the pace. Reply and pre-approvals today. | H10: =INDEX(Pipeline!$V$5:$V$14,MATCH($A10,Pipeline!$Y$5:$Y$14,0))&"" -> Reply to Sam today; Finance pre-approval (up to 12% on 2 years, net 60); call with Sam and Priya this week. Target signature 30 Nov. | I10: =INDEX(Pipeline!$W$5:$W$14,MATCH($A10,Pipeline!$Y$5:$Y$14,0)) -> Me | J10: =INDEX(Pipeline!$AA$5:$AA$14,MATCH($A10,Pipeline!$Y$5:$Y$14,0))&"" -> Me: reply to Sam, the call, the order form Finance: pre-approves up to 12% and net 60 VP CS: pre-approves the buffer | K10: =INDEX(Pipeline!$X$5:$X$14,MATCH($A10,Pipeline!$Y$5:$Y$14,0)) -> 46315 | L10: =INDEX(Pipeline!$AB$5:$AB$14,MATCH($A10,Pipeline!$Y$5:$Y$14,0))&""
A11: 7 | B11: =INDEX(Pipeline!$A$5:$A$14,MATCH($A11,Pipeline!$Y$5:$Y$14,0)) -> Marlowe Insurance | C11: =INDEX(Pipeline!$B$5:$B$14,MATCH($A11,Pipeline!$Y$5:$Y$14,0)) -> 46000 | D11: =INDEX(Pipeline!$C$5:$C$14,MATCH($A11,Pipeline!$Y$5:$Y$14,0)) -> 46365 | E11: =INDEX(Pipeline!$J$5:$J$14,MATCH($A11,Pipeline!$Y$5:$Y$14,0)) -> 50 | F11: =INDEX(Pipeline!$G$5:$G$14,MATCH($A11,Pipeline!$Y$5:$Y$14,0)) -> Engaging customer | G11: =INDEX(Pipeline!$Z$5:$Z$14,MATCH($A11,Pipeline!$Y$5:$Y$14,0))&"" -> Insurance procurement is slow; no DPA and questionnaire means no PO. | H11: =INDEX(Pipeline!$V$5:$V$14,MATCH($A11,Pipeline!$Y$5:$Y$14,0))&"" -> Quote sent with standard DPA and questionnaire (AI first draft, Security reviews) by 27 Oct. Work back from their PO lead time. | I11: =INDEX(Pipeline!$W$5:$W$14,MATCH($A11,Pipeline!$Y$5:$Y$14,0)) -> Me | J11: =INDEX(Pipeline!$AA$5:$AA$14,MATCH($A11,Pipeline!$Y$5:$Y$14,0))&"" -> Me: quote, questionnaire, PO lead time Security: reviews the questionnaire answers Legal: the DPA | K11: =INDEX(Pipeline!$X$5:$X$14,MATCH($A11,Pipeline!$Y$5:$Y$14,0)) -> 46322 | L11: =INDEX(Pipeline!$AB$5:$AB$14,MATCH($A11,Pipeline!$Y$5:$Y$14,0))&""
A12: 8 | B12: =INDEX(Pipeline!$A$5:$A$14,MATCH($A12,Pipeline!$Y$5:$Y$14,0)) -> Kestrel Analytics | C12: =INDEX(Pipeline!$B$5:$B$14,MATCH($A12,Pipeline!$Y$5:$Y$14,0)) -> 35000 | D12: =INDEX(Pipeline!$C$5:$C$14,MATCH($A12,Pipeline!$Y$5:$Y$14,0)) -> 46354 | E12: =INDEX(Pipeline!$J$5:$J$14,MATCH($A12,Pipeline!$Y$5:$Y$14,0)) -> 39 | F12: =INDEX(Pipeline!$G$5:$G$14,MATCH($A12,Pipeline!$Y$5:$Y$14,0)) -> Not started | G12: =INDEX(Pipeline!$Z$5:$Z$14,MATCH($A12,Pipeline!$Y$5:$Y$14,0))&"" -> Usage +40%, near the execution cap: expansion, and a throttling risk. | H12: =INDEX(Pipeline!$V$5:$V$14,MATCH($A12,Pipeline!$Y$5:$Y$14,0))&"" -> CSM usage review and approves the tier; one quote with renewal (€35k like-for-like) and upsell (next tier) as separate lines; upsell on its own linked Upsell opportunity. | I12: =INDEX(Pipeline!$W$5:$W$14,MATCH($A12,Pipeline!$Y$5:$Y$14,0)) -> CSM | J12: =INDEX(Pipeline!$AA$5:$AA$14,MATCH($A12,Pipeline!$Y$5:$Y$14,0))&"" -> CSM: usage review, approves the tier Me: one quote, renewal and upsell on separate lines; upsell opportunity | K12: =INDEX(Pipeline!$X$5:$X$14,MATCH($A12,Pipeline!$Y$5:$Y$14,0)) -> 46323 | L12: =INDEX(Pipeline!$AB$5:$AB$14,MATCH($A12,Pipeline!$Y$5:$Y$14,0))&""
A13: 9 | B13: =INDEX(Pipeline!$A$5:$A$14,MATCH($A13,Pipeline!$Y$5:$Y$14,0)) -> Lumen Retail | C13: =INDEX(Pipeline!$B$5:$B$14,MATCH($A13,Pipeline!$Y$5:$Y$14,0)) -> 28000 | D13: =INDEX(Pipeline!$C$5:$C$14,MATCH($A13,Pipeline!$Y$5:$Y$14,0)) -> 46347 | E13: =INDEX(Pipeline!$J$5:$J$14,MATCH($A13,Pipeline!$Y$5:$Y$14,0)) -> 32 | F13: =INDEX(Pipeline!$G$5:$G$14,MATCH($A13,Pipeline!$Y$5:$Y$14,0)) -> Billing blocker | G13: =INDEX(Pipeline!$Z$5:$Z$14,MATCH($A13,Pipeline!$Y$5:$Y$14,0))&"" -> Auto-renewal would invoice the wrong legal entity; cancellation deadline 22 Oct (assumed 30-day notice). | H13: =INDEX(Pipeline!$V$5:$V$14,MATCH($A13,Pipeline!$Y$5:$Y$14,0))&"" -> New entity details (name, VAT, address); Legal: billing change or assignment; Finance updates billing before the invoice run. Cancellation deadline 22 Oct (assumed 30 days). | I13: =INDEX(Pipeline!$W$5:$W$14,MATCH($A13,Pipeline!$Y$5:$Y$14,0)) -> Me | J13: =INDEX(Pipeline!$AA$5:$AA$14,MATCH($A13,Pipeline!$Y$5:$Y$14,0))&"" -> Me: gets the new entity's details Legal: billing change or assignment Finance: updates billing before the invoice run | K13: =INDEX(Pipeline!$X$5:$X$14,MATCH($A13,Pipeline!$Y$5:$Y$14,0)) -> 46317 | L13: =INDEX(Pipeline!$AB$5:$AB$14,MATCH($A13,Pipeline!$Y$5:$Y$14,0))&""
A14: 10 | B14: =INDEX(Pipeline!$A$5:$A$14,MATCH($A14,Pipeline!$Y$5:$Y$14,0)) -> Quanta Labs | C14: =INDEX(Pipeline!$B$5:$B$14,MATCH($A14,Pipeline!$Y$5:$Y$14,0)) -> 40000 | D14: =INDEX(Pipeline!$C$5:$C$14,MATCH($A14,Pipeline!$Y$5:$Y$14,0)) -> 46375 | E14: =INDEX(Pipeline!$J$5:$J$14,MATCH($A14,Pipeline!$Y$5:$Y$14,0)) -> 60 | F14: =INDEX(Pipeline!$G$5:$G$14,MATCH($A14,Pipeline!$Y$5:$Y$14,0)) -> At risk: before notice deadline | G14: =INDEX(Pipeline!$Z$5:$Z$14,MATCH($A14,Pipeline!$Y$5:$Y$14,0))&"" -> Auto-renewal, usage -20%, Q1 budget cuts, unresponsive. 60 days, but the notice deadline is ~19 Nov (assumed 30-day notice). | H14: =INDEX(Pipeline!$V$5:$V$14,MATCH($A14,Pipeline!$Y$5:$Y$14,0))&"" -> CSM and exec sponsor via a new contact; I confirm the ~19 Nov notice date; offer right-sizing or a 2-year price lock before they cancel. | I14: =INDEX(Pipeline!$W$5:$W$14,MATCH($A14,Pipeline!$Y$5:$Y$14,0)) -> CSM | J14: =INDEX(Pipeline!$AA$5:$AA$14,MATCH($A14,Pipeline!$Y$5:$Y$14,0))&"" -> CSM + exec sponsor: reach a new contact Me: confirms the notice date, offers the lock or right-size | K14: =INDEX(Pipeline!$X$5:$X$14,MATCH($A14,Pipeline!$Y$5:$Y$14,0)) -> 46325 | L14: =INDEX(Pipeline!$AB$5:$AB$14,MATCH($A14,Pipeline!$Y$5:$Y$14,0))&""
A16: Escalations today | C16: =COUNTIF(L5:L14,"Yes*")&" accounts, "&TEXT(SUMIF(L5:L14,"Yes*",C5:C14),"€#,##0")&" ARR" -> 3 accounts, €116,000 ARR
A17: Process | C17: 5 of 7 manual renewals inside 60 days have no quote on record (policy: quote at 60 days). Raise with my manager: 60-day quote task in the CRM, and the daily renewal alert (Part 3) drafting the renewal email with the quotation.

Sheet Pipeline
A1: Q4 2026 renewal pipeline: first slice (10 renewals, €375k ARR)
A2: Today | B2: 46315 | D2: Target date | E2: 46325 | G2: Blue on yellow = input. Everything else is a formula. Columns AF-AJ: the forecast on 30 Oct, with this week's actions (green) and with no action (red).
A4: Customer | B4: Base ARR (€) | C4: Renewal date | D4: Type | E4: Usage 90d | F4: Health | G4: Renewal Status | H4: Blocker | I4: Expected close | J4: Days to renewal | K4: Window | L4: Overdue? | M4: Month | N4: Quarter | O4: Quarter end | P4: Probability | Q4: Counts in quarter? | R4: Forecast prob. | S4: New ARR (€) | T4: Weighted new ARR (€) | U4: Forecast bucket | V4: Next action | W4: Owner | X4: Due | Y4: Rank | Z4: Why first | AA4: Who does what | AB4: Escalate today | AC4: Notice period (days) | AD4: Notice deadline | AE4: Usage signal | AF4: Target status by 30 Oct | AG4: Target prob. | AH4: Weighted after actions (€) | AI4: No-action prob. (30 Oct) | AJ4: Weighted, no action (€)
A5: Vantage Freight | B5: 21000 | C5: 46310 | D5: Manual | E5: 0 | F5: Yellow | G5: Quoted | H5: No named contact (shared inbox) | I5: 46332 | J5: =C5-$B$2 -> -5 | K5: =IF(J5<0,"Overdue",IF(J5<=30,"0-30",IF(J5<=60,"31-60",IF(J5<=90,"61-90",">90")))) -> Overdue | L5: =IF(AND(J5<0,G5<>"Closed won",G5<>"Cancelled"),"YES","") -> YES | M5: =TEXT(C5,"yyyy-mm") -> 2026-10 | N5: ="Q"&ROUNDUP(MONTH(C5)/3,0)&" "&YEAR(C5) -> Q4 2026 | O5: =EOMONTH(DATE(YEAR(C5),ROUNDUP(MONTH(C5)/3,0)*3,1),0) -> 46387 | P5: =INDEX(Probability!$B$5:$F$19,MATCH(G5,Probability!$A$5:$A$19,0),MATCH(K5,Probability!$B$4:$F$4,0)) -> 0.5 | Q5: =IF(I5<=O5,"Yes","No") -> Yes | R5: =IF(Q5="Yes",P5,0) -> 0.5 | S5: =SUMIFS(Products!$K:$K,Products!$A:$A,A5) -> 21000 | T5: =S5*R5 -> 10500 | U5: =IF(G5="Cancelled","Lost",IF(Q5="No","Slips quarter",IF(OR(J5<0,AND(J5<=30,OR(G5="--None--",G5="Not started",G5="Engaging customer",G5="Negotiation",G5="Billing blocker",G5="At risk: before notice deadline",G5="Notice received"))),"Late","On time"))) -> Late | V5: CSM looks up the instance owner and admin users (names, emails) in product data, to replace the shared inbox; I call and email the named person and agree a signing date. Manager confirms the grace period before access is restricted. | W5: Me | X5: 46316 | Y5: 2 | Z5: Already overdue. The blocker is a shared inbox, not price: find a named person. | AA5: CSM: finds the instance owner and admins Me: calls them and agrees a signing date Manager: confirms the grace period | AB5: Yes: Manager, to agree the grace period before access is restricted | AD5: =IF(AC5="","",C5-AC5) | AE5: =IF(E5>=0.2,"Over-usage: open Upsell opp + CSM/Renewals task",IF(E5<=-0.2,"Under-usage: flag CSM"&IF(D5="Auto","; set At risk",""),"")) | AF5: Waiting for PO | AG5: =IF(I5<=O5,INDEX(Probability!$B$5:$F$19,MATCH(AF5,Probability!$A$5:$A$19,0),MATCH(IF(C5-$E$2<0,"Overdue",IF(C5-$E$2<=30,"0-30",IF(C5-$E$2<=60,"31-60",IF(C5-$E$2<=90,"61-90",">90")))),Probability!$B$4:$F$4,0)),0) -> 0.7 | AH5: =S5*AG5 -> 14700 | AI5: =IF(I5<=O5,INDEX(Probability!$B$5:$F$19,MATCH(G5,Probability!$A$5:$A$19,0),MATCH(IF(C5-$E$2<0,"Overdue",IF(C5-$E$2<=30,"0-30",IF(C5-$E$2<=60,"31-60",IF(C5-$E$2<=90,"61-90",">90")))),Probability!$B$4:$F$4,0)),0) -> 0.5 | AJ5: =S5*AI5 -> 10500
A6: Northwind Logistics | B6: 48000 | C6: 46324 | D6: Manual | E6: 0.12 | F6: Green | G6: Engaging customer | H6: No quote sent; signatory unknown; signed 3 days late last year | I6: 46324 | J6: =C6-$B$2 -> 9 | K6: =IF(J6<0,"Overdue",IF(J6<=30,"0-30",IF(J6<=60,"31-60",IF(J6<=90,"61-90",">90")))) -> 0-30 | L6: =IF(AND(J6<0,G6<>"Closed won",G6<>"Cancelled"),"YES","") | M6: =TEXT(C6,"yyyy-mm") -> 2026-10 | N6: ="Q"&ROUNDUP(MONTH(C6)/3,0)&" "&YEAR(C6) -> Q4 2026 | O6: =EOMONTH(DATE(YEAR(C6),ROUNDUP(MONTH(C6)/3,0)*3,1),0) -> 46387 | P6: =INDEX(Probability!$B$5:$F$19,MATCH(G6,Probability!$A$5:$A$19,0),MATCH(K6,Probability!$B$4:$F$4,0)) -> 0.25 | Q6: =IF(I6<=O6,"Yes","No") -> Yes | R6: =IF(Q6="Yes",P6,0) -> 0.25 | S6: =SUMIFS(Products!$K:$K,Products!$A:$A,A6) -> 48000 | T6: =S6*R6 -> 12000 | U6: =IF(G6="Cancelled","Lost",IF(Q6="No","Slips quarter",IF(OR(J6<0,AND(J6<=30,OR(G6="--None--",G6="Not started",G6="Engaging customer",G6="Negotiation",G6="Billing blocker",G6="At risk: before notice deadline",G6="Notice received"))),"Late","On time"))) -> Late | V6: Quote and order form out today at €48k for e-signature; champion confirms signatory and PO need; signature booked for 27 Oct. | W6: Me | X6: 46315 | Y6: 1 | Z6: Biggest near-term ARR, 9 days out, no quote, signed 3 days late last year. One hour of work removes most of the risk. | AA6: Me: quote, order form, signatory, signature on 27 Oct | AD6: =IF(AC6="","",C6-AC6) | AE6: =IF(E6>=0.2,"Over-usage: open Upsell opp + CSM/Renewals task",IF(E6<=-0.2,"Under-usage: flag CSM"&IF(D6="Auto","; set At risk",""),"")) | AF6: PO received | AG6: =IF(I6<=O6,INDEX(Probability!$B$5:$F$19,MATCH(AF6,Probability!$A$5:$A$19,0),MATCH(IF(C6-$E$2<0,"Overdue",IF(C6-$E$2<=30,"0-30",IF(C6-$E$2<=60,"31-60",IF(C6-$E$2<=90,"61-90",">90")))),Probability!$B$4:$F$4,0)),0) -> 0.95 | AH6: =S6*AG6 -> 45600 | AI6: =IF(I6<=O6,INDEX(Probability!$B$5:$F$19,MATCH(G6,Probability!$A$5:$A$19,0),MATCH(IF(C6-$E$2<0,"Overdue",IF(C6-$E$2<=30,"0-30",IF(C6-$E$2<=60,"31-60",IF(C6-$E$2<=90,"61-90",">90")))),Probability!$B$4:$F$4,0)),0) -> 0.1 | AJ6: =S6*AI6 -> 4800
A7: Pixelforge | B7: 26000 | C7: 46328 | D7: Auto | E7: 0 | F7: Green | G7: Billing blocker | H7: Card expired; billing contact unknown | I7: 46328 | J7: =C7-$B$2 -> 13 | K7: =IF(J7<0,"Overdue",IF(J7<=30,"0-30",IF(J7<=60,"31-60",IF(J7<=90,"61-90",">90")))) -> 0-30 | L7: =IF(AND(J7<0,G7<>"Closed won",G7<>"Cancelled"),"YES","") | M7: =TEXT(C7,"yyyy-mm") -> 2026-11 | N7: ="Q"&ROUNDUP(MONTH(C7)/3,0)&" "&YEAR(C7) -> Q4 2026 | O7: =EOMONTH(DATE(YEAR(C7),ROUNDUP(MONTH(C7)/3,0)*3,1),0) -> 46387 | P7: =INDEX(Probability!$B$5:$F$19,MATCH(G7,Probability!$A$5:$A$19,0),MATCH(K7,Probability!$B$4:$F$4,0)) -> 0.6 | Q7: =IF(I7<=O7,"Yes","No") -> Yes | R7: =IF(Q7="Yes",P7,0) -> 0.6 | S7: =SUMIFS(Products!$K:$K,Products!$A:$A,A7) -> 26000 | T7: =S7*R7 -> 15600 | U7: =IF(G7="Cancelled","Lost",IF(Q7="No","Slips quarter",IF(OR(J7<0,AND(J7<=30,OR(G7="--None--",G7="Not started",G7="Engaging customer",G7="Negotiation",G7="Billing blocker",G7="At risk: before notice deadline",G7="Notice received"))),"Late","On time"))) -> Late | V7: CSM gets the billing contact today; I send a secure card-update link or switch to invoice; Finance pauses the automatic failed-payment process (reminders, retries, suspension) until the card is fixed. Renews at €26k (renewal value). | W7: CSM | X7: 46317 | Y7: 3 | Z7: Auto-renewal fails in 13 days on an expired card: involuntary churn on a green account. | AA7: CSM: finds the billing contact Me: card-update link or switch to invoice Finance: pauses the failed-payment process | AC7: 30 | AD7: =IF(AC7="","",C7-AC7) -> 46298 | AE7: =IF(E7>=0.2,"Over-usage: open Upsell opp + CSM/Renewals task",IF(E7<=-0.2,"Under-usage: flag CSM"&IF(D7="Auto","; set At risk",""),"")) | AF7: Renewing: no blockers | AG7: =IF(I7<=O7,INDEX(Probability!$B$5:$F$19,MATCH(AF7,Probability!$A$5:$A$19,0),MATCH(IF(C7-$E$2<0,"Overdue",IF(C7-$E$2<=30,"0-30",IF(C7-$E$2<=60,"31-60",IF(C7-$E$2<=90,"61-90",">90")))),Probability!$B$4:$F$4,0)),0) -> 0.97 | AH7: =S7*AG7 -> 25220 | AI7: =IF(I7<=O7,INDEX(Probability!$B$5:$F$19,MATCH(G7,Probability!$A$5:$A$19,0),MATCH(IF(C7-$E$2<0,"Overdue",IF(C7-$E$2<=30,"0-30",IF(C7-$E$2<=60,"31-60",IF(C7-$E$2<=90,"61-90",">90")))),Probability!$B$4:$F$4,0)),0) -> 0.6 | AJ7: =S7*AI7 -> 15600
A8: Halden Health | B8: 45000 | C8: 46333 | D8: Manual | E8: -0.35 | F8: Red | G8: Not started | H8: Champion left; new owner unknown | I8: 46346 | J8: =C8-$B$2 -> 18 | K8: =IF(J8<0,"Overdue",IF(J8<=30,"0-30",IF(J8<=60,"31-60",IF(J8<=90,"61-90",">90")))) -> 0-30 | L8: =IF(AND(J8<0,G8<>"Closed won",G8<>"Cancelled"),"YES","") | M8: =TEXT(C8,"yyyy-mm") -> 2026-11 | N8: ="Q"&ROUNDUP(MONTH(C8)/3,0)&" "&YEAR(C8) -> Q4 2026 | O8: =EOMONTH(DATE(YEAR(C8),ROUNDUP(MONTH(C8)/3,0)*3,1),0) -> 46387 | P8: =INDEX(Probability!$B$5:$F$19,MATCH(G8,Probability!$A$5:$A$19,0),MATCH(K8,Probability!$B$4:$F$4,0)) -> 0.1 | Q8: =IF(I8<=O8,"Yes","No") -> Yes | R8: =IF(Q8="Yes",P8,0) -> 0.1 | S8: =SUMIFS(Products!$K:$K,Products!$A:$A,A8) -> 30000 | T8: =S8*R8 -> 3000 | U8: =IF(G8="Cancelled","Lost",IF(Q8="No","Slips quarter",IF(OR(J8<0,AND(J8<=30,OR(G8="--None--",G8="Not started",G8="Engaging customer",G8="Negotiation",G8="Billing blocker",G8="At risk: before notice deadline",G8="Notice received"))),"Late","On time"))) -> Late | V8: ESCALATE TODAY. CSM, me and exec sponsor meet the new owner this week. Legal checks the 8 Oct notice date. Right-sized option ready. | W8: CSM | X8: 46318 | Y8: 4 | Z8: Red, usage -35%, champion gone, new owner unknown, 18 days left. | AA8: CSM (lead): meets the new owner, value review Exec sponsor: joins that meeting Legal: checks the 8 Oct notice date Me: escalates, prepares the right-sized option | AB8: Yes: Manager + VP CS, exec sponsor meeting with the new owner this week | AC8: 30 | AD8: =IF(AC8="","",C8-AC8) -> 46303 | AE8: =IF(E8>=0.2,"Over-usage: open Upsell opp + CSM/Renewals task",IF(E8<=-0.2,"Under-usage: flag CSM"&IF(D8="Auto","; set At risk",""),"")) -> Under-usage: flag CSM | AF8: Engaging customer | AG8: =IF(I8<=O8,INDEX(Probability!$B$5:$F$19,MATCH(AF8,Probability!$A$5:$A$19,0),MATCH(IF(C8-$E$2<0,"Overdue",IF(C8-$E$2<=30,"0-30",IF(C8-$E$2<=60,"31-60",IF(C8-$E$2<=90,"61-90",">90")))),Probability!$B$4:$F$4,0)),0) -> 0.25 | AH8: =S8*AG8 -> 7500 | AI8: =IF(I8<=O8,INDEX(Probability!$B$5:$F$19,MATCH(G8,Probability!$A$5:$A$19,0),MATCH(IF(C8-$E$2<0,"Overdue",IF(C8-$E$2<=30,"0-30",IF(C8-$E$2<=60,"31-60",IF(C8-$E$2<=90,"61-90",">90")))),Probability!$B$4:$F$4,0)),0) -> 0.1 | AJ8: =S8*AI8 -> 3000
A9: Brightloop | B9: 36000 | C9: 46370 | D9: Manual | E9: -0.1 | F9: Yellow | G9: Negotiation | H9: Procurement asks: 25% off, net 60, no auto-renew, 3-month TfC | I9: 46356 | J9: =C9-$B$2 -> 55 | K9: =IF(J9<0,"Overdue",IF(J9<=30,"0-30",IF(J9<=60,"31-60",IF(J9<=90,"61-90",">90")))) -> 31-60 | L9: =IF(AND(J9<0,G9<>"Closed won",G9<>"Cancelled"),"YES","") | M9: =TEXT(C9,"yyyy-mm") -> 2026-12 | N9: ="Q"&ROUNDUP(MONTH(C9)/3,0)&" "&YEAR(C9) -> Q4 2026 | O9: =EOMONTH(DATE(YEAR(C9),ROUNDUP(MONTH(C9)/3,0)*3,1),0) -> 46387 | P9: =INDEX(Probability!$B$5:$F$19,MATCH(G9,Probability!$A$5:$A$19,0),MATCH(K9,Probability!$B$4:$F$4,0)) -> 0.5 | Q9: =IF(I9<=O9,"Yes","No") -> Yes | R9: =IF(Q9="Yes",P9,0) -> 0.5 | S9: =SUMIFS(Products!$K:$K,Products!$A:$A,A9) -> 32400 | T9: =S9*R9 -> 16200 | U9: =IF(G9="Cancelled","Lost",IF(Q9="No","Slips quarter",IF(OR(J9<0,AND(J9<=30,OR(G9="--None--",G9="Not started",G9="Engaging customer",G9="Negotiation",G9="Billing blocker",G9="At risk: before notice deadline",G9="Notice received"))),"Late","On time"))) -> On time | V9: Reply to Sam today; Finance pre-approval (up to 12% on 2 years, net 60); call with Sam and Priya this week. Target signature 30 Nov. | W9: Me | X9: 46315 | Y9: 6 | Z9: Live negotiation; procurement sets the pace. Reply and pre-approvals today. | AA9: Me: reply to Sam, the call, the order form Finance: pre-approves up to 12% and net 60 VP CS: pre-approves the buffer | AD9: =IF(AC9="","",C9-AC9) | AE9: =IF(E9>=0.2,"Over-usage: open Upsell opp + CSM/Renewals task",IF(E9<=-0.2,"Under-usage: flag CSM"&IF(D9="Auto","; set At risk",""),"")) | AF9: Negotiation | AG9: =IF(I9<=O9,INDEX(Probability!$B$5:$F$19,MATCH(AF9,Probability!$A$5:$A$19,0),MATCH(IF(C9-$E$2<0,"Overdue",IF(C9-$E$2<=30,"0-30",IF(C9-$E$2<=60,"31-60",IF(C9-$E$2<=90,"61-90",">90")))),Probability!$B$4:$F$4,0)),0) -> 0.5 | AH9: =S9*AG9 -> 16200 | AI9: =IF(I9<=O9,INDEX(Probability!$B$5:$F$19,MATCH(G9,Probability!$A$5:$A$19,0),MATCH(IF(C9-$E$2<0,"Overdue",IF(C9-$E$2<=30,"0-30",IF(C9-$E$2<=60,"31-60",IF(C9-$E$2<=90,"61-90",">90")))),Probability!$B$4:$F$4,0)),0) -> 0.5 | AJ9: =S9*AI9 -> 16200
A10: Tessera Finance | B10: 50000 | C10: 46344 | D10: Manual | E10: 0.05 | F10: Yellow | G10: Negotiation | H10: MSA redlines open since Sep; security review | I10: 46360 | J10: =C10-$B$2 -> 29 | K10: =IF(J10<0,"Overdue",IF(J10<=30,"0-30",IF(J10<=60,"31-60",IF(J10<=90,"61-90",">90")))) -> 0-30 | L10: =IF(AND(J10<0,G10<>"Closed won",G10<>"Cancelled"),"YES","") | M10: =TEXT(C10,"yyyy-mm") -> 2026-11 | N10: ="Q"&ROUNDUP(MONTH(C10)/3,0)&" "&YEAR(C10) -> Q4 2026 | O10: =EOMONTH(DATE(YEAR(C10),ROUNDUP(MONTH(C10)/3,0)*3,1),0) -> 46387 | P10: =INDEX(Probability!$B$5:$F$19,MATCH(G10,Probability!$A$5:$A$19,0),MATCH(K10,Probability!$B$4:$F$4,0)) -> 0.4 | Q10: =IF(I10<=O10,"Yes","No") -> Yes | R10: =IF(Q10="Yes",P10,0) -> 0.4 | S10: =SUMIFS(Products!$K:$K,Products!$A:$A,A10) -> 50000 | T10: =S10*R10 -> 20000 | U10: =IF(G10="Cancelled","Lost",IF(Q10="No","Slips quarter",IF(OR(J10<0,AND(J10<=30,OR(G10="--None--",G10="Not started",G10="Engaging customer",G10="Negotiation",G10="Billing blocker",G10="At risk: before notice deadline",G10="Notice received"))),"Late","On time"))) -> Late | V10: ESCALATE TODAY to Legal: redline response by 30 Oct. List PO-blocking redlines, agree positions; joint redline call. Quote + security pack today. Fallback: 1-2 month extension if MSA not signed by 18 Nov. | W10: Legal | X10: 46318 | Y10: 5 | Z10: MSA redlines open since September and a security review can block the PO; 29 days left. | AA10: Legal (lead): positions on PO-blocking redlines, joint call, response by 30 Oct Me: redline list, quote and security pack, runs the timeline Finance + Legal: approve the extension fallback | AB10: Yes: Legal lead, redline response by 30 Oct; extension fallback approved | AD10: =IF(AC10="","",C10-AC10) | AE10: =IF(E10>=0.2,"Over-usage: open Upsell opp + CSM/Renewals task",IF(E10<=-0.2,"Under-usage: flag CSM"&IF(D10="Auto","; set At risk",""),"")) | AF10: Quoted | AG10: =IF(I10<=O10,INDEX(Probability!$B$5:$F$19,MATCH(AF10,Probability!$A$5:$A$19,0),MATCH(IF(C10-$E$2<0,"Overdue",IF(C10-$E$2<=30,"0-30",IF(C10-$E$2<=60,"31-60",IF(C10-$E$2<=90,"61-90",">90")))),Probability!$B$4:$F$4,0)),0) -> 0.75 | AH10: =S10*AG10 -> 37500 | AI10: =IF(I10<=O10,INDEX(Probability!$B$5:$F$19,MATCH(G10,Probability!$A$5:$A$19,0),MATCH(IF(C10-$E$2<0,"Overdue",IF(C10-$E$2<=30,"0-30",IF(C10-$E$2<=60,"31-60",IF(C10-$E$2<=90,"61-90",">90")))),Probability!$B$4:$F$4,0)),0) -> 0.4 | AJ10: =S10*AI10 -> 20000
A11: Lumen Retail | B11: 28000 | C11: 46347 | D11: Auto | E11: 0.08 | F11: Green | G11: Billing blocker | H11: Invoice to a different legal entity | I11: 46347 | J11: =C11-$B$2 -> 32 | K11: =IF(J11<0,"Overdue",IF(J11<=30,"0-30",IF(J11<=60,"31-60",IF(J11<=90,"61-90",">90")))) -> 31-60 | L11: =IF(AND(J11<0,G11<>"Closed won",G11<>"Cancelled"),"YES","") | M11: =TEXT(C11,"yyyy-mm") -> 2026-11 | N11: ="Q"&ROUNDUP(MONTH(C11)/3,0)&" "&YEAR(C11) -> Q4 2026 | O11: =EOMONTH(DATE(YEAR(C11),ROUNDUP(MONTH(C11)/3,0)*3,1),0) -> 46387 | P11: =INDEX(Probability!$B$5:$F$19,MATCH(G11,Probability!$A$5:$A$19,0),MATCH(K11,Probability!$B$4:$F$4,0)) -> 0.7 | Q11: =IF(I11<=O11,"Yes","No") -> Yes | R11: =IF(Q11="Yes",P11,0) -> 0.7 | S11: =SUMIFS(Products!$K:$K,Products!$A:$A,A11) -> 28000 | T11: =S11*R11 -> 19600 | U11: =IF(G11="Cancelled","Lost",IF(Q11="No","Slips quarter",IF(OR(J11<0,AND(J11<=30,OR(G11="--None--",G11="Not started",G11="Engaging customer",G11="Negotiation",G11="Billing blocker",G11="At risk: before notice deadline",G11="Notice received"))),"Late","On time"))) -> On time | V11: New entity details (name, VAT, address); Legal: billing change or assignment; Finance updates billing before the invoice run. Cancellation deadline 22 Oct (assumed 30 days). | W11: Me | X11: 46317 | Y11: 9 | Z11: Auto-renewal would invoice the wrong legal entity; cancellation deadline 22 Oct (assumed 30-day notice). | AA11: Me: gets the new entity's details Legal: billing change or assignment Finance: updates billing before the invoice run | AC11: 30 | AD11: =IF(AC11="","",C11-AC11) -> 46317 | AE11: =IF(E11>=0.2,"Over-usage: open Upsell opp + CSM/Renewals task",IF(E11<=-0.2,"Under-usage: flag CSM"&IF(D11="Auto","; set At risk",""),"")) | AF11: Renewing: no blockers | AG11: =IF(I11<=O11,INDEX(Probability!$B$5:$F$19,MATCH(AF11,Probability!$A$5:$A$19,0),MATCH(IF(C11-$E$2<0,"Overdue",IF(C11-$E$2<=30,"0-30",IF(C11-$E$2<=60,"31-60",IF(C11-$E$2<=90,"61-90",">90")))),Probability!$B$4:$F$4,0)),0) -> 0.97 | AH11: =S11*AG11 -> 27160 | AI11: =IF(I11<=O11,INDEX(Probability!$B$5:$F$19,MATCH(G11,Probability!$A$5:$A$19,0),MATCH(IF(C11-$E$2<0,"Overdue",IF(C11-$E$2<=30,"0-30",IF(C11-$E$2<=60,"31-60",IF(C11-$E$2<=90,"61-90",">90")))),Probability!$B$4:$F$4,0)),0) -> 0.6 | AJ11: =S11*AI11 -> 16800
A12: Kestrel Analytics | B12: 35000 | C12: 46354 | D12: Manual | E12: 0.4 | F12: Green | G12: Not started | H12: Close to execution cap | I12: 46354 | J12: =C12-$B$2 -> 39 | K12: =IF(J12<0,"Overdue",IF(J12<=30,"0-30",IF(J12<=60,"31-60",IF(J12<=90,"61-90",">90")))) -> 31-60 | L12: =IF(AND(J12<0,G12<>"Closed won",G12<>"Cancelled"),"YES","") | M12: =TEXT(C12,"yyyy-mm") -> 2026-11 | N12: ="Q"&ROUNDUP(MONTH(C12)/3,0)&" "&YEAR(C12) -> Q4 2026 | O12: =EOMONTH(DATE(YEAR(C12),ROUNDUP(MONTH(C12)/3,0)*3,1),0) -> 46387 | P12: =INDEX(Probability!$B$5:$F$19,MATCH(G12,Probability!$A$5:$A$19,0),MATCH(K12,Probability!$B$4:$F$4,0)) -> 0.2 | Q12: =IF(I12<=O12,"Yes","No") -> Yes | R12: =IF(Q12="Yes",P12,0) -> 0.2 | S12: =SUMIFS(Products!$K:$K,Products!$A:$A,A12) -> 35000 | T12: =S12*R12 -> 7000 | U12: =IF(G12="Cancelled","Lost",IF(Q12="No","Slips quarter",IF(OR(J12<0,AND(J12<=30,OR(G12="--None--",G12="Not started",G12="Engaging customer",G12="Negotiation",G12="Billing blocker",G12="At risk: before notice deadline",G12="Notice received"))),"Late","On time"))) -> On time | V12: CSM usage review and approves the tier; one quote with renewal (€35k like-for-like) and upsell (next tier) as separate lines; upsell on its own linked Upsell opportunity. | W12: CSM | X12: 46323 | Y12: 8 | Z12: Usage +40%, near the execution cap: expansion, and a throttling risk. | AA12: CSM: usage review, approves the tier Me: one quote, renewal and upsell on separate lines; upsell opportunity | AD12: =IF(AC12="","",C12-AC12) | AE12: =IF(E12>=0.2,"Over-usage: open Upsell opp + CSM/Renewals task",IF(E12<=-0.2,"Under-usage: flag CSM"&IF(D12="Auto","; set At risk",""),"")) -> Over-usage: open Upsell opp + CSM/Renewals task | AF12: Quoted | AG12: =IF(I12<=O12,INDEX(Probability!$B$5:$F$19,MATCH(AF12,Probability!$A$5:$A$19,0),MATCH(IF(C12-$E$2<0,"Overdue",IF(C12-$E$2<=30,"0-30",IF(C12-$E$2<=60,"31-60",IF(C12-$E$2<=90,"61-90",">90")))),Probability!$B$4:$F$4,0)),0) -> 0.75 | AH12: =S12*AG12 -> 26250 | AI12: =IF(I12<=O12,INDEX(Probability!$B$5:$F$19,MATCH(G12,Probability!$A$5:$A$19,0),MATCH(IF(C12-$E$2<0,"Overdue",IF(C12-$E$2<=30,"0-30",IF(C12-$E$2<=60,"31-60",IF(C12-$E$2<=90,"61-90",">90")))),Probability!$B$4:$F$4,0)),0) -> 0.1 | AJ12: =S12*AI12 -> 3500
A13: Marlowe Insurance | B13: 46000 | C13: 46365 | D13: Manual | E13: 0 | F13: Yellow | G13: Engaging customer | H13: Vendor questionnaire + DPA needed for PO | I13: 46365 | J13: =C13-$B$2 -> 50 | K13: =IF(J13<0,"Overdue",IF(J13<=30,"0-30",IF(J13<=60,"31-60",IF(J13<=90,"61-90",">90")))) -> 31-60 | L13: =IF(AND(J13<0,G13<>"Closed won",G13<>"Cancelled"),"YES","") | M13: =TEXT(C13,"yyyy-mm") -> 2026-12 | N13: ="Q"&ROUNDUP(MONTH(C13)/3,0)&" "&YEAR(C13) -> Q4 2026 | O13: =EOMONTH(DATE(YEAR(C13),ROUNDUP(MONTH(C13)/3,0)*3,1),0) -> 46387 | P13: =INDEX(Probability!$B$5:$F$19,MATCH(G13,Probability!$A$5:$A$19,0),MATCH(K13,Probability!$B$4:$F$4,0)) -> 0.35 | Q13: =IF(I13<=O13,"Yes","No") -> Yes | R13: =IF(Q13="Yes",P13,0) -> 0.35 | S13: =SUMIFS(Products!$K:$K,Products!$A:$A,A13) -> 46000 | T13: =S13*R13 -> 16100 | U13: =IF(G13="Cancelled","Lost",IF(Q13="No","Slips quarter",IF(OR(J13<0,AND(J13<=30,OR(G13="--None--",G13="Not started",G13="Engaging customer",G13="Negotiation",G13="Billing blocker",G13="At risk: before notice deadline",G13="Notice received"))),"Late","On time"))) -> On time | V13: Quote sent with standard DPA and questionnaire (AI first draft, Security reviews) by 27 Oct. Work back from their PO lead time. | W13: Me | X13: 46322 | Y13: 7 | Z13: Insurance procurement is slow; no DPA and questionnaire means no PO. | AA13: Me: quote, questionnaire, PO lead time Security: reviews the questionnaire answers Legal: the DPA | AD13: =IF(AC13="","",C13-AC13) | AE13: =IF(E13>=0.2,"Over-usage: open Upsell opp + CSM/Renewals task",IF(E13<=-0.2,"Under-usage: flag CSM"&IF(D13="Auto","; set At risk",""),"")) | AF13: Quoted | AG13: =IF(I13<=O13,INDEX(Probability!$B$5:$F$19,MATCH(AF13,Probability!$A$5:$A$19,0),MATCH(IF(C13-$E$2<0,"Overdue",IF(C13-$E$2<=30,"0-30",IF(C13-$E$2<=60,"31-60",IF(C13-$E$2<=90,"61-90",">90")))),Probability!$B$4:$F$4,0)),0) -> 0.7 | AH13: =S13*AG13 -> 32200 | AI13: =IF(I13<=O13,INDEX(Probability!$B$5:$F$19,MATCH(G13,Probability!$A$5:$A$19,0),MATCH(IF(C13-$E$2<0,"Overdue",IF(C13-$E$2<=30,"0-30",IF(C13-$E$2<=60,"31-60",IF(C13-$E$2<=90,"61-90",">90")))),Probability!$B$4:$F$4,0)),0) -> 0.35 | AJ13: =S13*AI13 -> 16100
A14: Quanta Labs | B14: 40000 | C14: 46375 | D14: Auto | E14: -0.2 | F14: Yellow | G14: At risk: before notice deadline | H14: Budget cuts in Q1; 2 check-ins unanswered | I14: 46375 | J14: =C14-$B$2 -> 60 | K14: =IF(J14<0,"Overdue",IF(J14<=30,"0-30",IF(J14<=60,"31-60",IF(J14<=90,"61-90",">90")))) -> 31-60 | L14: =IF(AND(J14<0,G14<>"Closed won",G14<>"Cancelled"),"YES","") | M14: =TEXT(C14,"yyyy-mm") -> 2026-12 | N14: ="Q"&ROUNDUP(MONTH(C14)/3,0)&" "&YEAR(C14) -> Q4 2026 | O14: =EOMONTH(DATE(YEAR(C14),ROUNDUP(MONTH(C14)/3,0)*3,1),0) -> 46387 | P14: =INDEX(Probability!$B$5:$F$19,MATCH(G14,Probability!$A$5:$A$19,0),MATCH(K14,Probability!$B$4:$F$4,0)) -> 0.4 | Q14: =IF(I14<=O14,"Yes","No") -> Yes | R14: =IF(Q14="Yes",P14,0) -> 0.4 | S14: =SUMIFS(Products!$K:$K,Products!$A:$A,A14) -> 32000 | T14: =S14*R14 -> 12800 | U14: =IF(G14="Cancelled","Lost",IF(Q14="No","Slips quarter",IF(OR(J14<0,AND(J14<=30,OR(G14="--None--",G14="Not started",G14="Engaging customer",G14="Negotiation",G14="Billing blocker",G14="At risk: before notice deadline",G14="Notice received"))),"Late","On time"))) -> On time | V14: CSM and exec sponsor via a new contact; I confirm the ~19 Nov notice date; offer right-sizing or a 2-year price lock before they cancel. | W14: CSM | X14: 46325 | Y14: 10 | Z14: Auto-renewal, usage -20%, Q1 budget cuts, unresponsive. 60 days, but the notice deadline is ~19 Nov (assumed 30-day notice). | AA14: CSM + exec sponsor: reach a new contact Me: confirms the notice date, offers the lock or right-size | AC14: 30 | AD14: =IF(AC14="","",C14-AC14) -> 46345 | AE14: =IF(E14>=0.2,"Over-usage: open Upsell opp + CSM/Renewals task",IF(E14<=-0.2,"Under-usage: flag CSM"&IF(D14="Auto","; set At risk",""),"")) -> Under-usage: flag CSM; set At risk | AF14: At risk: before notice deadline | AG14: =IF(I14<=O14,INDEX(Probability!$B$5:$F$19,MATCH(AF14,Probability!$A$5:$A$19,0),MATCH(IF(C14-$E$2<0,"Overdue",IF(C14-$E$2<=30,"0-30",IF(C14-$E$2<=60,"31-60",IF(C14-$E$2<=90,"61-90",">90")))),Probability!$B$4:$F$4,0)),0) -> 0.4 | AH14: =S14*AG14 -> 12800 | AI14: =IF(I14<=O14,INDEX(Probability!$B$5:$F$19,MATCH(G14,Probability!$A$5:$A$19,0),MATCH(IF(C14-$E$2<0,"Overdue",IF(C14-$E$2<=30,"0-30",IF(C14-$E$2<=60,"31-60",IF(C14-$E$2<=90,"61-90",">90")))),Probability!$B$4:$F$4,0)),0) -> 0.4 | AJ14: =S14*AI14 -> 12800
A15: Total | B15: =SUM(B5:B14) -> 375000 | S15: =SUM(S5:S14) -> 348400 | T15: =SUM(T5:T14) -> 132800 | AH15: =SUM(AH5:AH14) -> 245130 | AJ15: =SUM(AJ5:AJ14) -> 119300
A18: Q4 forecast vs €375k base ARR
A19: Bucket | B19: Weighted new ARR (€) | C19: Unweighted new ARR (€) | D19: Accounts
A20: On time | B20: =SUMIFS(T5:T14,U5:U14,"On time") -> 71700 | C20: =SUMIFS(S5:S14,U5:U14,"On time") -> 173400 | D20: =COUNTIFS(U5:U14,"On time")&" renewals" -> 5 renewals
A21: Late, still in quarter | B21: =SUMIFS(T5:T14,U5:U14,"Late") -> 61100 | C21: =SUMIFS(S5:S14,U5:U14,"Late") -> 175000 | D21: =COUNTIFS(U5:U14,"Late")&" renewals" -> 5 renewals
A22: Slips past quarter end (0%) | B22: =SUMIFS(T5:T14,U5:U14,"Slips quarter") -> 0 | C22: =SUMIFS(S5:S14,U5:U14,"Slips quarter") -> 0 | D22: =COUNTIFS(U5:U14,"Slips quarter")&" renewals" -> 0 renewals
A23: Total forecast (weighted) | B23: =SUM(B20:B22) -> 132800 | C23: =SUM(C20:C22) -> 348400
A24: Lost (from product lines)
A25: Regrettable churn / contraction | B25: ='Opp summary'!E15 -> -23000
A26: Non-regrettable churn (revenue kept) | B26: ='Opp summary'!F15 -> 0
A27: Price concession (discount) | B27: ='Opp summary'!H15 -> -3600
A28: Gross retention (base less regrettable churn and concessions) | B28: =(B15+B25+B27)/B15 -> 0.92906667
A29: Net retention (new ARR / base) | B29: =S15/B15 -> 0.92906667
A31: Forecast of the forecast
A32: Weighted today (statuses from what we know) | B32: =T15 -> 132800
A33: Weighted by 30 Oct, if this week's actions land | B33: =AH15 -> 245130
A34: Gain from this week's actions | B34: =B33-B32 -> 112330
A35: Weighted by 30 Oct with no action (statuses stay, the countdown runs) | B35: =AJ15 -> 119300
A36: Cost of doing nothing (vs today) | B36: =B35-B32 -> -13500
A37: Action power: with actions vs no action on 30 Oct | B37: =B33-B35 -> 125830

Sheet Products
A1: Opportunity products: the Renewals Manager only sets the line type and the new numbers; everything else recalculates
A2: Renewals Manager inputs (yellow): line type and change at list. Original ARR is the renewal value and already includes the 5% uplift (applied when the renewal opportunity is created), so nothing is added on top. On multi-year deals paid upfront the price is locked from year 2 (no further uplift); paid annually, 5% applies every year. An Upsell line opens a linked Upsell opportunity so expansion is forecast separately. Churn category and reason live on the opportunity.
A4: Opportunity | B4: Product | C4: Line type | D4: Term (yrs) | E4: Payment | F4: Original ARR (€) | G4: Change at list (€) | H4: Extra uplift % | I4: Discount % | J4: List renewal price (€) | K4: New ARR (€) | L4: Δ vs original (€) | M4: Δ % | N4: Approval needed | O4: Year 2+ uplift | P4: Note
A5: Vantage Freight | B5: n8n Cloud Business | C5: Renewal | D5: 1 | E5: Annual | F5: 21000 | G5: 0 | H5: 0 | I5: 0 | J5: =IF(C5="Churn",0,F5*(1+H5)+G5) -> 21000 | K5: =J5*(1-I5) -> 21000 | L5: =K5-F5 -> 0 | M5: =IF(F5=0,"new",L5/F5) -> 0 | N5: =IF(I5=0,"None",IF(AND(D5>=2,I5<=0.05),"None (multi-year)",IF(I5<=0.12,"Finance","VP Customer Success"))) -> None | O5: =IF(D5<2,"n/a",IF(E5="Upfront","Locked (0%)","5% a year")) -> n/a | P5: Quote of 1 Sep at the renewal value
A6: Northwind Logistics | B6: n8n Cloud Enterprise | C6: Renewal | D6: 1 | E6: Annual | F6: 48000 | G6: 0 | H6: 0 | I6: 0 | J6: =IF(C6="Churn",0,F6*(1+H6)+G6) -> 48000 | K6: =J6*(1-I6) -> 48000 | L6: =K6-F6 -> 0 | M6: =IF(F6=0,"new",L6/F6) -> 0 | N6: =IF(I6=0,"None",IF(AND(D6>=2,I6<=0.05),"None (multi-year)",IF(I6<=0.12,"Finance","VP Customer Success"))) -> None | O6: =IF(D6<2,"n/a",IF(E6="Upfront","Locked (0%)","5% a year")) -> n/a | P6: Usage +12%: check cap next quarter
A7: Pixelforge | B7: n8n Cloud Business | C7: Renewal | D7: 1 | E7: Annual | F7: 26000 | G7: 0 | H7: 0 | I7: 0 | J7: =IF(C7="Churn",0,F7*(1+H7)+G7) -> 26000 | K7: =J7*(1-I7) -> 26000 | L7: =K7-F7 -> 0 | M7: =IF(F7=0,"new",L7/F7) -> 0 | N7: =IF(I7=0,"None",IF(AND(D7>=2,I7<=0.05),"None (multi-year)",IF(I7<=0.12,"Finance","VP Customer Success"))) -> None | O7: =IF(D7<2,"n/a",IF(E7="Upfront","Locked (0%)","5% a year")) -> n/a | P7: Renewal value; the contractual uplift is already in it
A8: Halden Health | B8: n8n Enterprise (self-hosted) | C8: Downgrade | D8: 1 | E8: Annual | F8: 45000 | G8: -15000 | H8: 0 | I8: 0 | J8: =IF(C8="Churn",0,F8*(1+H8)+G8) -> 30000 | K8: =J8*(1-I8) -> 30000 | L8: =K8-F8 -> -15000 | M8: =IF(F8=0,"new",L8/F8) -> -0.33333333 | N8: =IF(I8=0,"None",IF(AND(D8>=2,I8<=0.05),"None (multi-year)",IF(I8<=0.12,"Finance","VP Customer Success"))) -> None | O8: =IF(D8<2,"n/a",IF(E8="Upfront","Locked (0%)","5% a year")) -> n/a | P8: Right-sized at list (assumed €30k)
A9: Brightloop | B9: n8n Enterprise | C9: Renewal | D9: 2 | E9: Annual | F9: 36000 | G9: 0 | H9: 0 | I9: 0.1 | J9: =IF(C9="Churn",0,F9*(1+H9)+G9) -> 36000 | K9: =J9*(1-I9) -> 32400 | L9: =K9-F9 -> -3600 | M9: =IF(F9=0,"new",L9/F9) -> -0.1 | N9: =IF(I9=0,"None",IF(AND(D9>=2,I9<=0.05),"None (multi-year)",IF(I9<=0.12,"Finance","VP Customer Success"))) -> Finance | O9: =IF(D9<2,"n/a",IF(E9="Upfront","Locked (0%)","5% a year")) -> 5% a year | P9: Ramp year 1: 10% off; year 2 €35,910
A10: Tessera Finance | B10: n8n Enterprise (self-hosted) | C10: Renewal | D10: 1 | E10: Annual | F10: 50000 | G10: 0 | H10: 0 | I10: 0 | J10: =IF(C10="Churn",0,F10*(1+H10)+G10) -> 50000 | K10: =J10*(1-I10) -> 50000 | L10: =K10-F10 -> 0 | M10: =IF(F10=0,"new",L10/F10) -> 0 | N10: =IF(I10=0,"None",IF(AND(D10>=2,I10<=0.05),"None (multi-year)",IF(I10<=0.12,"Finance","VP Customer Success"))) -> None | O10: =IF(D10<2,"n/a",IF(E10="Upfront","Locked (0%)","5% a year")) -> n/a
A11: Lumen Retail | B11: n8n Cloud Business | C11: Renewal | D11: 1 | E11: Annual | F11: 28000 | G11: 0 | H11: 0 | I11: 0 | J11: =IF(C11="Churn",0,F11*(1+H11)+G11) -> 28000 | K11: =J11*(1-I11) -> 28000 | L11: =K11-F11 -> 0 | M11: =IF(F11=0,"new",L11/F11) -> 0 | N11: =IF(I11=0,"None",IF(AND(D11>=2,I11<=0.05),"None (multi-year)",IF(I11<=0.12,"Finance","VP Customer Success"))) -> None | O11: =IF(D11<2,"n/a",IF(E11="Upfront","Locked (0%)","5% a year")) -> n/a | P11: Bill to new legal entity
A12: Kestrel Analytics | B12: n8n Cloud Business | C12: Renewal | D12: 1 | E12: Annual | F12: 35000 | G12: 0 | H12: 0 | I12: 0 | J12: =IF(C12="Churn",0,F12*(1+H12)+G12) -> 35000 | K12: =J12*(1-I12) -> 35000 | L12: =K12-F12 -> 0 | M12: =IF(F12=0,"new",L12/F12) -> 0 | N12: =IF(I12=0,"None",IF(AND(D12>=2,I12<=0.05),"None (multi-year)",IF(I12<=0.12,"Finance","VP Customer Success"))) -> None | O12: =IF(D12<2,"n/a",IF(E12="Upfront","Locked (0%)","5% a year")) -> n/a | P12: Commit line
A13: Kestrel Analytics | B13: Next execution tier | C13: Upsell | D13: 1 | E13: Annual | F13: 0 | G13: 0 | H13: 0 | I13: 0 | J13: =IF(C13="Churn",0,F13*(1+H13)+G13) -> 0 | K13: =J13*(1-I13) -> 0 | L13: =K13-F13 -> 0 | M13: =IF(F13=0,"new",L13/F13) -> new | N13: =IF(I13=0,"None",IF(AND(D13>=2,I13<=0.05),"None (multi-year)",IF(I13<=0.12,"Finance","VP Customer Success"))) -> None | O13: =IF(D13<2,"n/a",IF(E13="Upfront","Locked (0%)","5% a year")) -> n/a | P13: Opens a linked Upsell opportunity (upside)
A14: Marlowe Insurance | B14: n8n Cloud Enterprise | C14: Renewal | D14: 1 | E14: Annual | F14: 46000 | G14: 0 | H14: 0 | I14: 0 | J14: =IF(C14="Churn",0,F14*(1+H14)+G14) -> 46000 | K14: =J14*(1-I14) -> 46000 | L14: =K14-F14 -> 0 | M14: =IF(F14=0,"new",L14/F14) -> 0 | N14: =IF(I14=0,"None",IF(AND(D14>=2,I14<=0.05),"None (multi-year)",IF(I14<=0.12,"Finance","VP Customer Success"))) -> None | O14: =IF(D14<2,"n/a",IF(E14="Upfront","Locked (0%)","5% a year")) -> n/a
A15: Quanta Labs | B15: n8n Cloud Enterprise | C15: Downgrade | D15: 1 | E15: Annual | F15: 40000 | G15: -8000 | H15: 0 | I15: 0 | J15: =IF(C15="Churn",0,F15*(1+H15)+G15) -> 32000 | K15: =J15*(1-I15) -> 32000 | L15: =K15-F15 -> -8000 | M15: =IF(F15=0,"new",L15/F15) -> -0.2 | N15: =IF(I15=0,"None",IF(AND(D15>=2,I15<=0.05),"None (multi-year)",IF(I15<=0.12,"Finance","VP Customer Success"))) -> None | O15: =IF(D15<2,"n/a",IF(E15="Upfront","Locked (0%)","5% a year")) -> n/a | P15: Right-sized in line with -20% usage
A17: Total | F17: =SUM(F5:F15) -> 375000 | G17: =SUM(G5:G15) -> -23000 | J17: =SUM(J5:J15) -> 352000 | K17: =SUM(K5:K15) -> 348400 | L17: =SUM(L5:L15) -> -26600
A19: Assumptions
A20: Plan names and downgrade prices are assumptions: n8n does not publish self-hosted Enterprise prices. A year-1 uplift waiver is an exception (e.g. three years paid upfront) and counts as a discount under policy C.

Sheet Opp summary
A1: Opportunity roll-up: calculated from product lines; churn category and reason set on the opportunity
A3: Opportunity | B3: Original ARR (€) | C3: Extra uplift (€) | D3: Upsell (€) → Upsell opp | E3: Churned amount (€) | F3: Churn category | G3: Churn reason | H3: Price concession below current (€) | I3: New ARR (€) | J3: Net change (€) | K3: Net change %
A4: =Pipeline!A5 -> Vantage Freight | B4: =SUMIFS(Products!$F:$F,Products!$A:$A,$A4) -> 21000 | C4: =SUMPRODUCT((Products!$A$5:$A$200=$A4)*Products!$F$5:$F$200*Products!$H$5:$H$200) -> 0 | D4: =SUMIFS(Products!$G:$G,Products!$A:$A,$A4,Products!$C:$C,"Upsell") -> 0 | E4: =SUMIFS(Products!$G:$G,Products!$A:$A,$A4,Products!$C:$C,"Downgrade")-SUMIFS(Products!$F:$F,Products!$A:$A,$A4,Products!$C:$C,"Churn") -> 0 | H4: =MIN(0,C4-(SUMIFS(Products!$J:$J,Products!$A:$A,$A4)-SUMIFS(Products!$K:$K,Products!$A:$A,$A4))) -> 0 | I4: =SUMIFS(Products!$K:$K,Products!$A:$A,$A4) -> 21000 | J4: =I4-B4 -> 0 | K4: =IF(B4=0,0,J4/B4) -> 0
A5: =Pipeline!A6 -> Northwind Logistics | B5: =SUMIFS(Products!$F:$F,Products!$A:$A,$A5) -> 48000 | C5: =SUMPRODUCT((Products!$A$5:$A$200=$A5)*Products!$F$5:$F$200*Products!$H$5:$H$200) -> 0 | D5: =SUMIFS(Products!$G:$G,Products!$A:$A,$A5,Products!$C:$C,"Upsell") -> 0 | E5: =SUMIFS(Products!$G:$G,Products!$A:$A,$A5,Products!$C:$C,"Downgrade")-SUMIFS(Products!$F:$F,Products!$A:$A,$A5,Products!$C:$C,"Churn") -> 0 | H5: =MIN(0,C5-(SUMIFS(Products!$J:$J,Products!$A:$A,$A5)-SUMIFS(Products!$K:$K,Products!$A:$A,$A5))) -> 0 | I5: =SUMIFS(Products!$K:$K,Products!$A:$A,$A5) -> 48000 | J5: =I5-B5 -> 0 | K5: =IF(B5=0,0,J5/B5) -> 0
A6: =Pipeline!A7 -> Pixelforge | B6: =SUMIFS(Products!$F:$F,Products!$A:$A,$A6) -> 26000 | C6: =SUMPRODUCT((Products!$A$5:$A$200=$A6)*Products!$F$5:$F$200*Products!$H$5:$H$200) -> 0 | D6: =SUMIFS(Products!$G:$G,Products!$A:$A,$A6,Products!$C:$C,"Upsell") -> 0 | E6: =SUMIFS(Products!$G:$G,Products!$A:$A,$A6,Products!$C:$C,"Downgrade")-SUMIFS(Products!$F:$F,Products!$A:$A,$A6,Products!$C:$C,"Churn") -> 0 | H6: =MIN(0,C6-(SUMIFS(Products!$J:$J,Products!$A:$A,$A6)-SUMIFS(Products!$K:$K,Products!$A:$A,$A6))) -> 0 | I6: =SUMIFS(Products!$K:$K,Products!$A:$A,$A6) -> 26000 | J6: =I6-B6 -> 0 | K6: =IF(B6=0,0,J6/B6) -> 0
A7: =Pipeline!A8 -> Halden Health | B7: =SUMIFS(Products!$F:$F,Products!$A:$A,$A7) -> 45000 | C7: =SUMPRODUCT((Products!$A$5:$A$200=$A7)*Products!$F$5:$F$200*Products!$H$5:$H$200) -> 0 | D7: =SUMIFS(Products!$G:$G,Products!$A:$A,$A7,Products!$C:$C,"Upsell") -> 0 | E7: =SUMIFS(Products!$G:$G,Products!$A:$A,$A7,Products!$C:$C,"Downgrade")-SUMIFS(Products!$F:$F,Products!$A:$A,$A7,Products!$C:$C,"Churn") -> -15000 | F7: Regrettable | G7: Low adoption / champion left | H7: =MIN(0,C7-(SUMIFS(Products!$J:$J,Products!$A:$A,$A7)-SUMIFS(Products!$K:$K,Products!$A:$A,$A7))) -> 0 | I7: =SUMIFS(Products!$K:$K,Products!$A:$A,$A7) -> 30000 | J7: =I7-B7 -> -15000 | K7: =IF(B7=0,0,J7/B7) -> -0.33333333
A8: =Pipeline!A9 -> Brightloop | B8: =SUMIFS(Products!$F:$F,Products!$A:$A,$A8) -> 36000 | C8: =SUMPRODUCT((Products!$A$5:$A$200=$A8)*Products!$F$5:$F$200*Products!$H$5:$H$200) -> 0 | D8: =SUMIFS(Products!$G:$G,Products!$A:$A,$A8,Products!$C:$C,"Upsell") -> 0 | E8: =SUMIFS(Products!$G:$G,Products!$A:$A,$A8,Products!$C:$C,"Downgrade")-SUMIFS(Products!$F:$F,Products!$A:$A,$A8,Products!$C:$C,"Churn") -> 0 | H8: =MIN(0,C8-(SUMIFS(Products!$J:$J,Products!$A:$A,$A8)-SUMIFS(Products!$K:$K,Products!$A:$A,$A8))) -> -3600 | I8: =SUMIFS(Products!$K:$K,Products!$A:$A,$A8) -> 32400 | J8: =I8-B8 -> -3600 | K8: =IF(B8=0,0,J8/B8) -> -0.1
A9: =Pipeline!A10 -> Tessera Finance | B9: =SUMIFS(Products!$F:$F,Products!$A:$A,$A9) -> 50000 | C9: =SUMPRODUCT((Products!$A$5:$A$200=$A9)*Products!$F$5:$F$200*Products!$H$5:$H$200) -> 0 | D9: =SUMIFS(Products!$G:$G,Products!$A:$A,$A9,Products!$C:$C,"Upsell") -> 0 | E9: =SUMIFS(Products!$G:$G,Products!$A:$A,$A9,Products!$C:$C,"Downgrade")-SUMIFS(Products!$F:$F,Products!$A:$A,$A9,Products!$C:$C,"Churn") -> 0 | H9: =MIN(0,C9-(SUMIFS(Products!$J:$J,Products!$A:$A,$A9)-SUMIFS(Products!$K:$K,Products!$A:$A,$A9))) -> 0 | I9: =SUMIFS(Products!$K:$K,Products!$A:$A,$A9) -> 50000 | J9: =I9-B9 -> 0 | K9: =IF(B9=0,0,J9/B9) -> 0
A10: =Pipeline!A11 -> Lumen Retail | B10: =SUMIFS(Products!$F:$F,Products!$A:$A,$A10) -> 28000 | C10: =SUMPRODUCT((Products!$A$5:$A$200=$A10)*Products!$F$5:$F$200*Products!$H$5:$H$200) -> 0 | D10: =SUMIFS(Products!$G:$G,Products!$A:$A,$A10,Products!$C:$C,"Upsell") -> 0 | E10: =SUMIFS(Products!$G:$G,Products!$A:$A,$A10,Products!$C:$C,"Downgrade")-SUMIFS(Products!$F:$F,Products!$A:$A,$A10,Products!$C:$C,"Churn") -> 0 | H10: =MIN(0,C10-(SUMIFS(Products!$J:$J,Products!$A:$A,$A10)-SUMIFS(Products!$K:$K,Products!$A:$A,$A10))) -> 0 | I10: =SUMIFS(Products!$K:$K,Products!$A:$A,$A10) -> 28000 | J10: =I10-B10 -> 0 | K10: =IF(B10=0,0,J10/B10) -> 0
A11: =Pipeline!A12 -> Kestrel Analytics | B11: =SUMIFS(Products!$F:$F,Products!$A:$A,$A11) -> 35000 | C11: =SUMPRODUCT((Products!$A$5:$A$200=$A11)*Products!$F$5:$F$200*Products!$H$5:$H$200) -> 0 | D11: =SUMIFS(Products!$G:$G,Products!$A:$A,$A11,Products!$C:$C,"Upsell") -> 0 | E11: =SUMIFS(Products!$G:$G,Products!$A:$A,$A11,Products!$C:$C,"Downgrade")-SUMIFS(Products!$F:$F,Products!$A:$A,$A11,Products!$C:$C,"Churn") -> 0 | H11: =MIN(0,C11-(SUMIFS(Products!$J:$J,Products!$A:$A,$A11)-SUMIFS(Products!$K:$K,Products!$A:$A,$A11))) -> 0 | I11: =SUMIFS(Products!$K:$K,Products!$A:$A,$A11) -> 35000 | J11: =I11-B11 -> 0 | K11: =IF(B11=0,0,J11/B11) -> 0
A12: =Pipeline!A13 -> Marlowe Insurance | B12: =SUMIFS(Products!$F:$F,Products!$A:$A,$A12) -> 46000 | C12: =SUMPRODUCT((Products!$A$5:$A$200=$A12)*Products!$F$5:$F$200*Products!$H$5:$H$200) -> 0 | D12: =SUMIFS(Products!$G:$G,Products!$A:$A,$A12,Products!$C:$C,"Upsell") -> 0 | E12: =SUMIFS(Products!$G:$G,Products!$A:$A,$A12,Products!$C:$C,"Downgrade")-SUMIFS(Products!$F:$F,Products!$A:$A,$A12,Products!$C:$C,"Churn") -> 0 | H12: =MIN(0,C12-(SUMIFS(Products!$J:$J,Products!$A:$A,$A12)-SUMIFS(Products!$K:$K,Products!$A:$A,$A12))) -> 0 | I12: =SUMIFS(Products!$K:$K,Products!$A:$A,$A12) -> 46000 | J12: =I12-B12 -> 0 | K12: =IF(B12=0,0,J12/B12) -> 0
A13: =Pipeline!A14 -> Quanta Labs | B13: =SUMIFS(Products!$F:$F,Products!$A:$A,$A13) -> 40000 | C13: =SUMPRODUCT((Products!$A$5:$A$200=$A13)*Products!$F$5:$F$200*Products!$H$5:$H$200) -> 0 | D13: =SUMIFS(Products!$G:$G,Products!$A:$A,$A13,Products!$C:$C,"Upsell") -> 0 | E13: =SUMIFS(Products!$G:$G,Products!$A:$A,$A13,Products!$C:$C,"Downgrade")-SUMIFS(Products!$F:$F,Products!$A:$A,$A13,Products!$C:$C,"Churn") -> -8000 | F13: Regrettable | G13: Budget cut | H13: =MIN(0,C13-(SUMIFS(Products!$J:$J,Products!$A:$A,$A13)-SUMIFS(Products!$K:$K,Products!$A:$A,$A13))) -> 0 | I13: =SUMIFS(Products!$K:$K,Products!$A:$A,$A13) -> 32000 | J13: =I13-B13 -> -8000 | K13: =IF(B13=0,0,J13/B13) -> -0.2
A14: Total | B14: =SUM(B4:B13) -> 375000 | C14: =SUM(C4:C13) -> 0 | D14: =SUM(D4:D13) -> 0 | E14: =SUM(E4:E13) -> -23000 | H14: =SUM(H4:H13) -> -3600 | I14: =SUM(I4:I13) -> 348400 | J14: =SUM(J4:J13) -> -26600 | K14: =IF(B14=0,0,J14/B14) -> -0.070933333
A15: (linked to Pipeline) | E15: =SUMIFS(E4:E13,F4:F13,"Regrettable") -> -23000 | F15: =SUMIFS(E4:E13,F4:F13,"Non-regrettable") -> 0 | H15: =H14 -> -3600
A16: Churn reasons | B16: Regrettable: Budget cut · Regrettable: Price · Regrettable: Competitor · Regrettable: Moved to free Community edition · Regrettable: Product gaps · Regrettable: Support or service · Regrettable: Low adoption / champion left · Regrettable: Company closed · Non-regrettable: Migrated to another n8n product · Non-regrettable: Consolidated into another n8n contract · Non-regrettable: Moved to another legal entity
A17: Missing reason | B17: =COUNTIFS(E4:E13,"<0",F4:F13,"")&" opportunities with churn but no category" -> 0 opportunities with churn but no category
A18: Check: new ARR ties to Pipeline | B18: =IF(ABS(I14-Pipeline!S15)<1,"OK","MISMATCH") -> OK

Sheet Monthly report
A1: Renewals by quarter and month (by renewal date)
A3: Quarter | B3: Month | C3: # renewals | D3: Base ARR (€) | E3: New ARR (€) | F3: Weighted (€) | G3: On time, weighted (€) | H3: Late, weighted (€) | I3: Overdue ARR (€) | J3: Regrettable churn (€)
A4: Q4 2026 | B4: 2026-10 | C4: =COUNTIFS(Pipeline!$M$5:$M$14,B4) -> 2 | D4: =SUMIFS(Pipeline!$B$5:$B$14,Pipeline!$M$5:$M$14,B4) -> 69000 | E4: =SUMIFS(Pipeline!$S$5:$S$14,Pipeline!$M$5:$M$14,B4) -> 69000 | F4: =SUMIFS(Pipeline!$T$5:$T$14,Pipeline!$M$5:$M$14,B4) -> 22500 | G4: =SUMIFS(Pipeline!$T$5:$T$14,Pipeline!$M$5:$M$14,B4,Pipeline!$U$5:$U$14,"On time") -> 0 | H4: =SUMIFS(Pipeline!$T$5:$T$14,Pipeline!$M$5:$M$14,B4,Pipeline!$U$5:$U$14,"Late") -> 22500 | I4: =SUMIFS(Pipeline!$B$5:$B$14,Pipeline!$M$5:$M$14,B4,Pipeline!$L$5:$L$14,"YES") -> 21000 | J4: =SUMPRODUCT((TEXT(Pipeline!$C$5:$C$14,"yyyy-mm")=B4)*('Opp summary'!$F$4:$F$13="Regrettable")*'Opp summary'!$E$4:$E$13) -> 0
A5: Q4 2026 | B5: 2026-11 | C5: =COUNTIFS(Pipeline!$M$5:$M$14,B5) -> 5 | D5: =SUMIFS(Pipeline!$B$5:$B$14,Pipeline!$M$5:$M$14,B5) -> 184000 | E5: =SUMIFS(Pipeline!$S$5:$S$14,Pipeline!$M$5:$M$14,B5) -> 169000 | F5: =SUMIFS(Pipeline!$T$5:$T$14,Pipeline!$M$5:$M$14,B5) -> 65200 | G5: =SUMIFS(Pipeline!$T$5:$T$14,Pipeline!$M$5:$M$14,B5,Pipeline!$U$5:$U$14,"On time") -> 26600 | H5: =SUMIFS(Pipeline!$T$5:$T$14,Pipeline!$M$5:$M$14,B5,Pipeline!$U$5:$U$14,"Late") -> 38600 | I5: =SUMIFS(Pipeline!$B$5:$B$14,Pipeline!$M$5:$M$14,B5,Pipeline!$L$5:$L$14,"YES") -> 0 | J5: =SUMPRODUCT((TEXT(Pipeline!$C$5:$C$14,"yyyy-mm")=B5)*('Opp summary'!$F$4:$F$13="Regrettable")*'Opp summary'!$E$4:$E$13) -> -15000
A6: Q4 2026 | B6: 2026-12 | C6: =COUNTIFS(Pipeline!$M$5:$M$14,B6) -> 3 | D6: =SUMIFS(Pipeline!$B$5:$B$14,Pipeline!$M$5:$M$14,B6) -> 122000 | E6: =SUMIFS(Pipeline!$S$5:$S$14,Pipeline!$M$5:$M$14,B6) -> 110400 | F6: =SUMIFS(Pipeline!$T$5:$T$14,Pipeline!$M$5:$M$14,B6) -> 45100 | G6: =SUMIFS(Pipeline!$T$5:$T$14,Pipeline!$M$5:$M$14,B6,Pipeline!$U$5:$U$14,"On time") -> 45100 | H6: =SUMIFS(Pipeline!$T$5:$T$14,Pipeline!$M$5:$M$14,B6,Pipeline!$U$5:$U$14,"Late") -> 0 | I6: =SUMIFS(Pipeline!$B$5:$B$14,Pipeline!$M$5:$M$14,B6,Pipeline!$L$5:$L$14,"YES") -> 0 | J6: =SUMPRODUCT((TEXT(Pipeline!$C$5:$C$14,"yyyy-mm")=B6)*('Opp summary'!$F$4:$F$13="Regrettable")*'Opp summary'!$E$4:$E$13) -> -8000
A7: Q4 2026 total | C7: =SUM(C4:C6) -> 10 | D7: =SUM(D4:D6) -> 375000 | E7: =SUM(E4:E6) -> 348400 | F7: =SUM(F4:F6) -> 132800 | G7: =SUM(G4:G6) -> 71700 | H7: =SUM(H4:H6) -> 61100 | I7: =SUM(I4:I6) -> 21000 | J7: =SUM(J4:J6) -> -23000

Sheet Probability
A1: Renewal probability: Renewal Status x days to renewal
A2: Manual: late statuses (Quoted and after) rise as the date gets closer; early statuses fall. Auto-renewal: a clean renewal rises; an open blocker or risk falls as the date gets closer. Blue = editable.
A4: Renewal Status | B4: Overdue | C4: 0-30 | D4: 31-60 | E4: 61-90 | F4: >90 | G4: Exit criteria (what must be true to be in this status) | H4: Applies to
A5: --None-- | B5: 0 | C5: 0 | D5: 0 | E5: 0 | F5: 0 | G5: Not allowed. Every open renewal must have a status. | H5: Manual
A6: Not started | B6: 0.05 | C6: 0.1 | D6: 0.2 | E6: 0.3 | F6: 0.35 | G6: Renewal opportunity exists; no customer contact about the renewal yet. | H6: Manual
A7: Engaging customer | B7: 0.1 | C7: 0.25 | D7: 0.35 | E7: 0.45 | F7: 0.5 | G7: Decision maker and signatory known; renewal timeline agreed. | H7: Manual
A8: Negotiation | B8: 0.2 | C8: 0.4 | D8: 0.5 | E8: 0.55 | F8: 0.55 | G8: Commercial terms under discussion; customer asks are in writing. | H8: Manual
A9: Quoted | B9: 0.5 | C9: 0.75 | D9: 0.7 | E9: 0.65 | F9: 0.6 | G9: Final quote and order form sent and accepted by the champion. | H9: Manual
A10: Waiting for PO | B10: 0.7 | C10: 0.9 | D10: 0.85 | E10: 0.8 | F10: 0.75 | G10: Order form approved by the buyer; in their PO or signature workflow. | H10: Manual
A11: PO received | B11: 0.95 | C11: 0.99 | D11: 0.97 | E11: 0.95 | F11: 0.9 | G11: PO or signature in hand; only booking and invoicing remain. | H11: Manual
A12: Closed won | B12: 1 | C12: 1 | D12: 1 | E12: 1 | F12: 1 | G12: Signed, booked, invoiced. (Suggested addition to the picklist.) | H12: Manual
A13: Cancelled | B13: 0 | C13: 0 | D13: 0 | E13: 0 | F13: 0 | G13: Customer gave notice or will not renew. | H13: Both
A14: Renewing: no blockers | B14: 0.4 | C14: 0.97 | D14: 0.95 | E14: 0.92 | F14: 0.9 | G14: Valid payment method, correct billing entity, usage stable or growing. (Overdue = payment failed: move to Billing blocker.) | H14: Auto
